Workbook

Sheet Dashboard
A1: SwingScope Momentum Batch 2026-09-28 — 21-Day Dashboard
A2: Signal 2026-09-28 • Day 18 of 21 • Holding • Exit ~2026-10-29 • Updated 23-Oct-2026 17:22
B4: PROGRESS Day 18/21
L5: 86%
B7: CURRENT DAY | E7: LAST SESSION | H7: INVESTED | K7: MARKET VALUE
B8: Day 18 / 21 | E8: 2026-10-23 | H8: ='Daily Closes'!E16 | K8: ='Daily Closes'!AB16
B9: Holding | E9: Exit ~2026-10-29 | H9: Qty × entry price | K9: At latest close
B11: GROSS P&L | E11: GROSS RETURN | H11: EST. COSTS | K11: NET P&L
B12: ='Daily Closes'!AD16 | E12: ='Daily Closes'!AC16 | H12: ='Daily Closes'!E16*0.006 | K12: =B12-H12
B13: Before costs | E13: vs entry | H13: 0.6% round trip | K13: After est. costs
B15: NIFTY 50 | E15: ALPHA vs NIFTY | H15: WINNERS / LOSERS | K15: MAX DRAWDOWN
B16: -0.0079125558 | E16: -0.080260754 | H16: 0 / 10 | K16: -0.15058472
B17: Same window | E17: Gross return − Nifty | H17: of 10 stocks | K17: Peak-to-trough, portfolio
B19: STOCK LEAGUE TABLE (sorted by return)
B20: Symbol | C20: Qty | D20: Entry ₹ | E20: Last ₹ | F20: Return % | G20: P&L ₹ | H20: Max gain % | I20: Max loss % | J20: Weight % | K20: Contrib %
B21: LAURUSLABS | C21: 7 | D21: 2020.7 | E21: 1970 | F21: -0.02509 | G21: -354.9 | H21: 0.024002 | I21: -0.02509 | J21: 0.101067 | K21: -0.002536
B22: ACUTAAS | C22: 4 | D22: 3290 | E22: 3137.7 | F22: -0.046292 | G22: -609.2 | H22: 0.004286 | I22: -0.070912 | J22: 0.09403 | K22: -0.004353
B23: ATHERENERG | C23: 10 | D23: 1460.2 | E23: 1380 | F23: -0.054924 | G23: -802 | H23: 0.03479 | I23: -0.054924 | J23: 0.104333 | K23: -0.00573
B24: THANGAMAYL | C24: 2 | D24: 5010 | E24: 4690.5 | F24: -0.063772 | G24: -639 | H24: 0.038822 | I24: -0.063772 | J24: 0.071594 | K24: -0.004566
B25: DIACABS | C25: 44 | D25: 336.9 | E25: 315.05 | F25: -0.064856 | G25: -961.4 | H25: 0.130751 | I25: -0.064856 | J25: 0.105917 | K25: -0.006869
B26: E2E | C26: 23 | D26: 619.55 | E26: 566.05 | F26: -0.086353 | G26: -1230.5 | H26: 0.207812 | I26: -0.086353 | J26: 0.101816 | K26: -0.008792
B27: TDPOWERSYS | C27: 20 | D27: 719 | E27: 639.55 | F27: -0.110501 | G27: -1589 | H27: 0.148331 | I27: -0.110501 | J27: 0.102747 | K27: -0.011354
B28: AEROFLEX | C28: 29 | D28: 511.3 | E28: 451.3 | F28: -0.117348 | G28: -1740 | H28: 0.112263 | I28: -0.117348 | J28: 0.105946 | K28: -0.012433
B29: RRKABEL | C29: 6 | D29: 2459.8 | E29: 2140 | F29: -0.130011 | G29: -1918.8 | H29: 0.134117 | I29: -0.130011 | J29: 0.105454 | K29: -0.01371
B30: KIRLOSENG | C30: 7 | D30: 2141.2 | E30: 1784.7 | F30: -0.166495 | G30: -2495.5 | H30: 0.121801 | I30: -0.166495 | J30: 0.107094 | K30: -0.017831

Sheet Daily Closes
A1: SwingScope Batch 2026-09-28 — Daily Close Tracker
A2: Signal 2026-09-28 • Day 18 of 21 • Holding • Exit ~2026-10-29 • Updated 23-Oct-2026 17:22
A3: Closes from Day 0 (signal) to Day 21 (exit). Highlighted column = latest session. Grey = future session (projected date).
A4: # | B4: Symbol | C4: ISIN | D4: Qty | E4: Entry ₹ | F4: Day 0 | G4: Day 1 | H4: Day 2 | I4: Day 3 | J4: Day 4 | K4: Day 5 | L4: Day 6 | M4: Day 7 | N4: Day 8 | O4: Day 9 | P4: Day 10 | Q4: Day 11 | R4: Day 12 | S4: Day 13 | T4: Day 14 | U4: Day 15 | V4: Day 16 | W4: Day 17 | X4: Day 18 | Y4: Day 19 | Z4: Day 20 | AA4: Day 21 | AB4: Last Close | AC4: Return % | AD4: P&L ₹ | AE4: Day Chg % | AF4: Trend
F5: 28-Sep | G5: 29-Sep | H5: 30-Sep | I5: 01-Oct | J5: 02-Oct | K5: 05-Oct | L5: 06-Oct | M5: 07-Oct | N5: 08-Oct | O5: 09-Oct | P5: 12-Oct | Q5: 13-Oct | R5: 14-Oct | S5: 15-Oct | T5: 16-Oct | U5: 19-Oct | V5: 21-Oct | W5: 22-Oct | X5: 23-Oct | Y5: 27-Oct (p) | Z5: 28-Oct (p) | AA5: 29-Oct (p)
A6: 1 | B6: TDPOWERSYS | C6: INE419M01035 | D6: 20 | E6: 719 | F6: 722 | G6: 777.35 | H6: 786.05 | I6: 792.15 | J6: 792.15 | K6: 812.9 | L6: 816 | M6: 821.1 | N6: 793.5 | O6: 793.75 | P6: 825.65 | Q6: 797.85 | R6: 783.7 | S6: 734.75 | T6: 735.15 | U6: 737 | V6: 689.35 | W6: 673.4 | X6: 639.55 | AB6: =LOOKUP(2,1/(F6:AA6<>""),F6:AA6) | AC6: =AB6/E6-1 | AD6: =D6*(AB6-E6) | AE6: =IFERROR(X6/W6-1,0) | AF6: =IF(AC6>0,"▲ Up",IF(AC6<0,"▼ Down","■ Flat"))
A7: 2 | B7: AEROFLEX | C7: INE024001021 | D7: 29 | E7: 511.3 | F7: 513.4 | G7: 539.6 | H7: 536.6 | I7: 521.35 | J7: 521.35 | K7: 544.35 | L7: 560.75 | M7: 563.85 | N7: 529 | O7: 520.5 | P7: 567.9 | Q7: 557.6 | R7: 568.7 | S7: 510.95 | T7: 525.8 | U7: 505.2 | V7: 488.95 | W7: 479.45 | X7: 451.3 | AB7: =LOOKUP(2,1/(F7:AA7<>""),F7:AA7) | AC7: =AB7/E7-1 | AD7: =D7*(AB7-E7) | AE7: =IFERROR(X7/W7-1,0) | AF7: =IF(AC7>0,"▲ Up",IF(AC7<0,"▼ Down","■ Flat"))
A8: 3 | B8: ATHERENERG | C8: INE0LEZ01016 | D8: 10 | E8: 1460.2 | F8: 1454.9 | G8: 1407 | H8: 1425 | I8: 1406.1 | J8: 1406.1 | K8: 1409.9 | L8: 1446 | M8: 1455 | N8: 1406 | O8: 1434.4 | P8: 1511 | Q8: 1494.9 | R8: 1467 | S8: 1470 | T8: 1470 | U8: 1459 | V8: 1447.2 | W8: 1425.3 | X8: 1380 | AB8: =LOOKUP(2,1/(F8:AA8<>""),F8:AA8) | AC8: =AB8/E8-1 | AD8: =D8*(AB8-E8) | AE8: =IFERROR(X8/W8-1,0) | AF8: =IF(AC8>0,"▲ Up",IF(AC8<0,"▼ Down","■ Flat"))
A9: 4 | B9: THANGAMAYL | C9: INE085J01014 | D9: 2 | E9: 5010 | F9: 5011.5 | G9: 5204.5 | H9: 5062 | I9: 4861 | J9: 4861 | K9: 4747 | L9: 4758.5 | M9: 4803 | N9: 4810.5 | O9: 4889.5 | P9: 4890.5 | Q9: 4900.5 | R9: 4849.5 | S9: 4791 | T9: 5098 | U9: 5017.5 | V9: 4860.5 | W9: 4782.5 | X9: 4690.5 | AB9: =LOOKUP(2,1/(F9:AA9<>""),F9:AA9) | AC9: =AB9/E9-1 | AD9: =D9*(AB9-E9) | AE9: =IFERROR(X9/W9-1,0) | AF9: =IF(AC9>0,"▲ Up",IF(AC9<0,"▼ Down","■ Flat"))
A10: 5 | B10: RRKABEL | C10: INE777K01022 | D10: 6 | E10: 2459.8 | F10: 2459.8 | G10: 2523.2 | H10: 2518.6 | I10: 2518.2 | J10: 2518.2 | K10: 2648 | L10: 2789.7 | M10: 2722.5 | N10: 2696.4 | O10: 2705.6 | P10: 2721.5 | Q10: 2614.2 | R10: 2664.1 | S10: 2603.9 | T10: 2388 | U10: 2387.8 | V10: 2327.8 | W10: 2263.1 | X10: 2140 | AB10: =LOOKUP(2,1/(F10:AA10<>""),F10:AA10) | AC10: =AB10/E10-1 | AD10: =D10*(AB10-E10) | AE10: =IFERROR(X10/W10-1,0) | AF10: =IF(AC10>0,"▲ Up",IF(AC10<0,"▼ Down","■ Flat"))
A11: 6 | B11: ACUTAAS | C11: INE00FF01025 | D11: 4 | E11: 3290 | F11: 3214.4 | G11: 3304.1 | H11: 3279.4 | I11: 3196.5 | J11: 3196.5 | K11: 3122.2 | L11: 3156.7 | M11: 3174.2 | N11: 3056.7 | O11: 3160.6 | P11: 3144.1 | Q11: 3176.7 | R11: 3160.5 | S11: 3132.5 | T11: 3206 | U11: 3253.4 | V11: 3152.4 | W11: 3215.3 | X11: 3137.7 | AB11: =LOOKUP(2,1/(F11:AA11<>""),F11:AA11) | AC11: =AB11/E11-1 | AD11: =D11*(AB11-E11) | AE11: =IFERROR(X11/W11-1,0) | AF11: =IF(AC11>0,"▲ Up",IF(AC11<0,"▼ Down","■ Flat"))
A12: 7 | B12: DIACABS | C12: INE989C01038 | D12: 44 | E12: 336.9 | F12: 339.25 | G12: 352.05 | H12: 354.2 | I12: 345 | J12: 345 | K12: 350.8 | L12: 368.3 | M12: 369.15 | N12: 371.9 | O12: 380.95 | P12: 379.7 | Q12: 377.55 | R12: 378.75 | S12: 373.75 | T12: 362.4 | U12: 345.85 | V12: 337.85 | W12: 326.65 | X12: 315.05 | AB12: =LOOKUP(2,1/(F12:AA12<>""),F12:AA12) | AC12: =AB12/E12-1 | AD12: =D12*(AB12-E12) | AE12: =IFERROR(X12/W12-1,0) | AF12: =IF(AC12>0,"▲ Up",IF(AC12<0,"▼ Down","■ Flat"))
A13: 8 | B13: KIRLOSENG | C13: INE146L01010 | D13: 7 | E13: 2141.2 | F13: 2141.2 | G13: 2402 | H13: 2304.2 | I13: 2242.7 | J13: 2242.7 | K13: 2243.7 | L13: 2266.1 | M13: 2230.8 | N13: 2163 | O13: 2210.4 | P13: 2193 | Q13: 2180.8 | R13: 2148.3 | S13: 2066.3 | T13: 2025.6 | U13: 1973.2 | V13: 1908.7 | W13: 1869 | X13: 1784.7 | AB13: =LOOKUP(2,1/(F13:AA13<>""),F13:AA13) | AC13: =AB13/E13-1 | AD13: =D13*(AB13-E13) | AE13: =IFERROR(X13/W13-1,0) | AF13: =IF(AC13>0,"▲ Up",IF(AC13<0,"▼ Down","■ Flat"))
A14: 9 | B14: E2E | C14: INE255Z01027 | D14: 23 | E14: 619.55 | F14: 625.9 | G14: 651.8 | H14: 650.5 | I14: 648 | J14: 648 | K14: 656.1 | L14: 688.9 | M14: 723.3 | N14: 714.15 | O14: 704.6 | P14: 735.55 | Q14: 735.75 | R14: 748.3 | S14: 710.9 | T14: 694.85 | U14: 660.15 | V14: 627.15 | W14: 595.8 | X14: 566.05 | AB14: =LOOKUP(2,1/(F14:AA14<>""),F14:AA14) | AC14: =AB14/E14-1 | AD14: =D14*(AB14-E14) | AE14: =IFERROR(X14/W14-1,0) | AF14: =IF(AC14>0,"▲ Up",IF(AC14<0,"▼ Down","■ Flat"))
A15: 10 | B15: LAURUSLABS | C15: INE947Q01028 | D15: 7 | E15: 2020.7 | F15: 2010.7 | G15: 1979 | H15: 1980 | I15: 1984 | J15: 1984 | K15: 1971.4 | L15: 2050 | M15: 2052.8 | N15: 1997.9 | O15: 2036.6 | P15: 2069.2 | Q15: 2059.4 | R15: 2036.9 | S15: 2018.5 | T15: 2060.1 | U15: 2069 | V15: 2012.5 | W15: 2002.5 | X15: 1970 | AB15: =LOOKUP(2,1/(F15:AA15<>""),F15:AA15) | AC15: =AB15/E15-1 | AD15: =D15*(AB15-E15) | AE15: =IFERROR(X15/W15-1,0) | AF15: =IF(AC15>0,"▲ Up",IF(AC15<0,"▼ Down","■ Flat"))
B16: PORTFOLIO | D16: =SUM(D6:D15) | E16: =SUMPRODUCT(D6:D15,E6:E15) | F16: =IF(COUNT(F6:F15)=0,"",SUMPRODUCT($D$6:$D$15,F6:F15)) | G16: =IF(COUNT(G6:G15)=0,"",SUMPRODUCT($D$6:$D$15,G6:G15)) | H16: =IF(COUNT(H6:H15)=0,"",SUMPRODUCT($D$6:$D$15,H6:H15)) | I16: =IF(COUNT(I6:I15)=0,"",SUMPRODUCT($D$6:$D$15,I6:I15)) | J16: =IF(COUNT(J6:J15)=0,"",SUMPRODUCT($D$6:$D$15,J6:J15)) | K16: =IF(COUNT(K6:K15)=0,"",SUMPRODUCT($D$6:$D$15,K6:K15)) | L16: =IF(COUNT(L6:L15)=0,"",SUMPRODUCT($D$6:$D$15,L6:L15)) | M16: =IF(COUNT(M6:M15)=0,"",SUMPRODUCT($D$6:$D$15,M6:M15)) | ... AA16: =IF(COUNT(AA6:AA15)=0,"",SUMPRODUCT($D$6:$D$15,AA6:AA15)) | AB16: =SUMPRODUCT(D6:D15,AB6:AB15) | AC16: =AB16/E16-1 | AD16: =SUM(AD6:AD15)

Sheet Returns %
A1: Cumulative Return vs Entry (%)
A2: Each cell = close ÷ entry − 1. Colour scale: red → white → green.
A3: Formulas link to 'Daily Closes' — edit a close there and this sheet updates.
A4: # | B4: Symbol | C4: ISIN | D4: Qty | E4: Entry ₹ | F4: Day 0 | G4: Day 1 | H4: Day 2 | I4: Day 3 | J4: Day 4 | K4: Day 5 | L4: Day 6 | M4: Day 7 | N4: Day 8 | O4: Day 9 | P4: Day 10 | Q4: Day 11 | R4: Day 12 | S4: Day 13 | T4: Day 14 | U4: Day 15 | V4: Day 16 | W4: Day 17 | X4: Day 18 | Y4: Day 19 | Z4: Day 20 | AA4: Day 21
F5: ='Daily Closes'!F5 | G5: ='Daily Closes'!G5 | H5: ='Daily Closes'!H5 | I5: ='Daily Closes'!I5 | J5: ='Daily Closes'!J5 | K5: ='Daily Closes'!K5 | L5: ='Daily Closes'!L5 | M5: ='Daily Closes'!M5 | ... AA5: ='Daily Closes'!AA5
A6: ='Daily Closes'!A6 | B6: ='Daily Closes'!B6 | C6: ='Daily Closes'!C6 | D6: ='Daily Closes'!D6 | E6: ='Daily Closes'!E6 | F6: — | G6: =IF('Daily Closes'!G6="","",'Daily Closes'!G6/$E6-1) | H6: =IF('Daily Closes'!H6="","",'Daily Closes'!H6/$E6-1) | I6: =IF('Daily Closes'!I6="","",'Daily Closes'!I6/$E6-1) | J6: =IF('Daily Closes'!J6="","",'Daily Closes'!J6/$E6-1) | K6: =IF('Daily Closes'!K6="","",'Daily Closes'!K6/$E6-1) | L6: =IF('Daily Closes'!L6="","",'Daily Closes'!L6/$E6-1) | M6: =IF('Daily Closes'!M6="","",'Daily Closes'!M6/$E6-1) | N6: =IF('Daily Closes'!N6="","",'Daily Closes'!N6/$E6-1) | ... AA6: =IF('Daily Closes'!AA6="","",'Daily Closes'!AA6/$E6-1)
A7: ='Daily Closes'!A7 | B7: ='Daily Closes'!B7 | C7: ='Daily Closes'!C7 | D7: ='Daily Closes'!D7 | E7: ='Daily Closes'!E7 | F7: — | G7: =IF('Daily Closes'!G7="","",'Daily Closes'!G7/$E7-1) | H7: =IF('Daily Closes'!H7="","",'Daily Closes'!H7/$E7-1) | I7: =IF('Daily Closes'!I7="","",'Daily Closes'!I7/$E7-1) | J7: =IF('Daily Closes'!J7="","",'Daily Closes'!J7/$E7-1) | K7: =IF('Daily Closes'!K7="","",'Daily Closes'!K7/$E7-1) | L7: =IF('Daily Closes'!L7="","",'Daily Closes'!L7/$E7-1) | M7: =IF('Daily Closes'!M7="","",'Daily Closes'!M7/$E7-1) | N7: =IF('Daily Closes'!N7="","",'Daily Closes'!N7/$E7-1) | ... AA7: =IF('Daily Closes'!AA7="","",'Daily Closes'!AA7/$E7-1)
A8: ='Daily Closes'!A8 | B8: ='Daily Closes'!B8 | C8: ='Daily Closes'!C8 | D8: ='Daily Closes'!D8 | E8: ='Daily Closes'!E8 | F8: — | G8: =IF('Daily Closes'!G8="","",'Daily Closes'!G8/$E8-1) | H8: =IF('Daily Closes'!H8="","",'Daily Closes'!H8/$E8-1) | I8: =IF('Daily Closes'!I8="","",'Daily Closes'!I8/$E8-1) | J8: =IF('Daily Closes'!J8="","",'Daily Closes'!J8/$E8-1) | K8: =IF('Daily Closes'!K8="","",'Daily Closes'!K8/$E8-1) | L8: =IF('Daily Closes'!L8="","",'Daily Closes'!L8/$E8-1) | M8: =IF('Daily Closes'!M8="","",'Daily Closes'!M8/$E8-1) | N8: =IF('Daily Closes'!N8="","",'Daily Closes'!N8/$E8-1) | ... AA8: =IF('Daily Closes'!AA8="","",'Daily Closes'!AA8/$E8-1)
A9: ='Daily Closes'!A9 | B9: ='Daily Closes'!B9 | C9: ='Daily Closes'!C9 | D9: ='Daily Closes'!D9 | E9: ='Daily Closes'!E9 | F9: — | G9: =IF('Daily Closes'!G9="","",'Daily Closes'!G9/$E9-1) | H9: =IF('Daily Closes'!H9="","",'Daily Closes'!H9/$E9-1) | I9: =IF('Daily Closes'!I9="","",'Daily Closes'!I9/$E9-1) | J9: =IF('Daily Closes'!J9="","",'Daily Closes'!J9/$E9-1) | K9: =IF('Daily Closes'!K9="","",'Daily Closes'!K9/$E9-1) | L9: =IF('Daily Closes'!L9="","",'Daily Closes'!L9/$E9-1) | M9: =IF('Daily Closes'!M9="","",'Daily Closes'!M9/$E9-1) | N9: =IF('Daily Closes'!N9="","",'Daily Closes'!N9/$E9-1) | ... AA9: =IF('Daily Closes'!AA9="","",'Daily Closes'!AA9/$E9-1)
A10: ='Daily Closes'!A10 | B10: ='Daily Closes'!B10 | C10: ='Daily Closes'!C10 | D10: ='Daily Closes'!D10 | E10: ='Daily Closes'!E10 | F10: — | G10: =IF('Daily Closes'!G10="","",'Daily Closes'!G10/$E10-1) | H10: =IF('Daily Closes'!H10="","",'Daily Closes'!H10/$E10-1) | I10: =IF('Daily Closes'!I10="","",'Daily Closes'!I10/$E10-1) | J10: =IF('Daily Closes'!J10="","",'Daily Closes'!J10/$E10-1) | K10: =IF('Daily Closes'!K10="","",'Daily Closes'!K10/$E10-1) | L10: =IF('Daily Closes'!L10="","",'Daily Closes'!L10/$E10-1) | M10: =IF('Daily Closes'!M10="","",'Daily Closes'!M10/$E10-1) | N10: =IF('Daily Closes'!N10="","",'Daily Closes'!N10/$E10-1) | ... AA10: =IF('Daily Closes'!AA10="","",'Daily Closes'!AA10/$E10-1)
A11: ='Daily Closes'!A11 | B11: ='Daily Closes'!B11 | C11: ='Daily Closes'!C11 | D11: ='Daily Closes'!D11 | E11: ='Daily Closes'!E11 | F11: — | G11: =IF('Daily Closes'!G11="","",'Daily Closes'!G11/$E11-1) | H11: =IF('Daily Closes'!H11="","",'Daily Closes'!H11/$E11-1) | I11: =IF('Daily Closes'!I11="","",'Daily Closes'!I11/$E11-1) | J11: =IF('Daily Closes'!J11="","",'Daily Closes'!J11/$E11-1) | K11: =IF('Daily Closes'!K11="","",'Daily Closes'!K11/$E11-1) | L11: =IF('Daily Closes'!L11="","",'Daily Closes'!L11/$E11-1) | M11: =IF('Daily Closes'!M11="","",'Daily Closes'!M11/$E11-1) | N11: =IF('Daily Closes'!N11="","",'Daily Closes'!N11/$E11-1) | ... AA11: =IF('Daily Closes'!AA11="","",'Daily Closes'!AA11/$E11-1)
A12: ='Daily Closes'!A12 | B12: ='Daily Closes'!B12 | C12: ='Daily Closes'!C12 | D12: ='Daily Closes'!D12 | E12: ='Daily Closes'!E12 | F12: — | G12: =IF('Daily Closes'!G12="","",'Daily Closes'!G12/$E12-1) | H12: =IF('Daily Closes'!H12="","",'Daily Closes'!H12/$E12-1) | I12: =IF('Daily Closes'!I12="","",'Daily Closes'!I12/$E12-1) | J12: =IF('Daily Closes'!J12="","",'Daily Closes'!J12/$E12-1) | K12: =IF('Daily Closes'!K12="","",'Daily Closes'!K12/$E12-1) | L12: =IF('Daily Closes'!L12="","",'Daily Closes'!L12/$E12-1) | M12: =IF('Daily Closes'!M12="","",'Daily Closes'!M12/$E12-1) | N12: =IF('Daily Closes'!N12="","",'Daily Closes'!N12/$E12-1) | ... AA12: =IF('Daily Closes'!AA12="","",'Daily Closes'!AA12/$E12-1)
A13: ='Daily Closes'!A13 | B13: ='Daily Closes'!B13 | C13: ='Daily Closes'!C13 | D13: ='Daily Closes'!D13 | E13: ='Daily Closes'!E13 | F13: — | G13: =IF('Daily Closes'!G13="","",'Daily Closes'!G13/$E13-1) | H13: =IF('Daily Closes'!H13="","",'Daily Closes'!H13/$E13-1) | I13: =IF('Daily Closes'!I13="","",'Daily Closes'!I13/$E13-1) | J13: =IF('Daily Closes'!J13="","",'Daily Closes'!J13/$E13-1) | K13: =IF('Daily Closes'!K13="","",'Daily Closes'!K13/$E13-1) | L13: =IF('Daily Closes'!L13="","",'Daily Closes'!L13/$E13-1) | M13: =IF('Daily Closes'!M13="","",'Daily Closes'!M13/$E13-1) | N13: =IF('Daily Closes'!N13="","",'Daily Closes'!N13/$E13-1) | ... AA13: =IF('Daily Closes'!AA13="","",'Daily Closes'!AA13/$E13-1)
A14: ='Daily Closes'!A14 | B14: ='Daily Closes'!B14 | C14: ='Daily Closes'!C14 | D14: ='Daily Closes'!D14 | E14: ='Daily Closes'!E14 | F14: — | G14: =IF('Daily Closes'!G14="","",'Daily Closes'!G14/$E14-1) | H14: =IF('Daily Closes'!H14="","",'Daily Closes'!H14/$E14-1) | I14: =IF('Daily Closes'!I14="","",'Daily Closes'!I14/$E14-1) | J14: =IF('Daily Closes'!J14="","",'Daily Closes'!J14/$E14-1) | K14: =IF('Daily Closes'!K14="","",'Daily Closes'!K14/$E14-1) | L14: =IF('Daily Closes'!L14="","",'Daily Closes'!L14/$E14-1) | M14: =IF('Daily Closes'!M14="","",'Daily Closes'!M14/$E14-1) | N14: =IF('Daily Closes'!N14="","",'Daily Closes'!N14/$E14-1) | ... AA14: =IF('Daily Closes'!AA14="","",'Daily Closes'!AA14/$E14-1)
A15: ='Daily Closes'!A15 | B15: ='Daily Closes'!B15 | C15: ='Daily Closes'!C15 | D15: ='Daily Closes'!D15 | E15: ='Daily Closes'!E15 | F15: — | G15: =IF('Daily Closes'!G15="","",'Daily Closes'!G15/$E15-1) | H15: =IF('Daily Closes'!H15="","",'Daily Closes'!H15/$E15-1) | I15: =IF('Daily Closes'!I15="","",'Daily Closes'!I15/$E15-1) | J15: =IF('Daily Closes'!J15="","",'Daily Closes'!J15/$E15-1) | K15: =IF('Daily Closes'!K15="","",'Daily Closes'!K15/$E15-1) | L15: =IF('Daily Closes'!L15="","",'Daily Closes'!L15/$E15-1) | M15: =IF('Daily Closes'!M15="","",'Daily Closes'!M15/$E15-1) | N15: =IF('Daily Closes'!N15="","",'Daily Closes'!N15/$E15-1) | ... AA15: =IF('Daily Closes'!AA15="","",'Daily Closes'!AA15/$E15-1)
B16: PORTFOLIO | G16: =IF('Daily Closes'!G16="","",'Daily Closes'!G16/'Daily Closes'!$E$16-1) | H16: =IF('Daily Closes'!H16="","",'Daily Closes'!H16/'Daily Closes'!$E$16-1) | I16: =IF('Daily Closes'!I16="","",'Daily Closes'!I16/'Daily Closes'!$E$16-1) | J16: =IF('Daily Closes'!J16="","",'Daily Closes'!J16/'Daily Closes'!$E$16-1) | K16: =IF('Daily Closes'!K16="","",'Daily Closes'!K16/'Daily Closes'!$E$16-1) | L16: =IF('Daily Closes'!L16="","",'Daily Closes'!L16/'Daily Closes'!$E$16-1) | M16: =IF('Daily Closes'!M16="","",'Daily Closes'!M16/'Daily Closes'!$E$16-1) | N16: =IF('Daily Closes'!N16="","",'Daily Closes'!N16/'Daily Closes'!$E$16-1) | ... AA16: =IF('Daily Closes'!AA16="","",'Daily Closes'!AA16/'Daily Closes'!$E$16-1)

Sheet P&L
A1: Mark-to-Market P&L (₹)
A2: Qty × (close − entry). Gross of costs.
A4: # | B4: Symbol | C4: ISIN | D4: Qty | E4: Entry ₹ | F4: Day 0 | G4: Day 1 | H4: Day 2 | I4: Day 3 | J4: Day 4 | K4: Day 5 | L4: Day 6 | M4: Day 7 | N4: Day 8 | O4: Day 9 | P4: Day 10 | Q4: Day 11 | R4: Day 12 | S4: Day 13 | T4: Day 14 | U4: Day 15 | V4: Day 16 | W4: Day 17 | X4: Day 18 | Y4: Day 19 | Z4: Day 20 | AA4: Day 21
A6: ='Daily Closes'!A6 | B6: ='Daily Closes'!B6 | C6: ='Daily Closes'!C6 | D6: ='Daily Closes'!D6 | E6: ='Daily Closes'!E6 | F6: — | G6: =IF('Daily Closes'!G6="","",$D6*('Daily Closes'!G6-$E6)) | H6: =IF('Daily Closes'!H6="","",$D6*('Daily Closes'!H6-$E6)) | I6: =IF('Daily Closes'!I6="","",$D6*('Daily Closes'!I6-$E6)) | J6: =IF('Daily Closes'!J6="","",$D6*('Daily Closes'!J6-$E6)) | K6: =IF('Daily Closes'!K6="","",$D6*('Daily Closes'!K6-$E6)) | L6: =IF('Daily Closes'!L6="","",$D6*('Daily Closes'!L6-$E6)) | M6: =IF('Daily Closes'!M6="","",$D6*('Daily Closes'!M6-$E6)) | N6: =IF('Daily Closes'!N6="","",$D6*('Daily Closes'!N6-$E6)) | ... AA6: =IF('Daily Closes'!AA6="","",$D6*('Daily Closes'!AA6-$E6))
A7: ='Daily Closes'!A7 | B7: ='Daily Closes'!B7 | C7: ='Daily Closes'!C7 | D7: ='Daily Closes'!D7 | E7: ='Daily Closes'!E7 | F7: — | G7: =IF('Daily Closes'!G7="","",$D7*('Daily Closes'!G7-$E7)) | H7: =IF('Daily Closes'!H7="","",$D7*('Daily Closes'!H7-$E7)) | I7: =IF('Daily Closes'!I7="","",$D7*('Daily Closes'!I7-$E7)) | J7: =IF('Daily Closes'!J7="","",$D7*('Daily Closes'!J7-$E7)) | K7: =IF('Daily Closes'!K7="","",$D7*('Daily Closes'!K7-$E7)) | L7: =IF('Daily Closes'!L7="","",$D7*('Daily Closes'!L7-$E7)) | M7: =IF('Daily Closes'!M7="","",$D7*('Daily Closes'!M7-$E7)) | N7: =IF('Daily Closes'!N7="","",$D7*('Daily Closes'!N7-$E7)) | ... AA7: =IF('Daily Closes'!AA7="","",$D7*('Daily Closes'!AA7-$E7))
A8: ='Daily Closes'!A8 | B8: ='Daily Closes'!B8 | C8: ='Daily Closes'!C8 | D8: ='Daily Closes'!D8 | E8: ='Daily Closes'!E8 | F8: — | G8: =IF('Daily Closes'!G8="","",$D8*('Daily Closes'!G8-$E8)) | H8: =IF('Daily Closes'!H8="","",$D8*('Daily Closes'!H8-$E8)) | I8: =IF('Daily Closes'!I8="","",$D8*('Daily Closes'!I8-$E8)) | J8: =IF('Daily Closes'!J8="","",$D8*('Daily Closes'!J8-$E8)) | K8: =IF('Daily Closes'!K8="","",$D8*('Daily Closes'!K8-$E8)) | L8: =IF('Daily Closes'!L8="","",$D8*('Daily Closes'!L8-$E8)) | M8: =IF('Daily Closes'!M8="","",$D8*('Daily Closes'!M8-$E8)) | N8: =IF('Daily Closes'!N8="","",$D8*('Daily Closes'!N8-$E8)) | ... AA8: =IF('Daily Closes'!AA8="","",$D8*('Daily Closes'!AA8-$E8))
A9: ='Daily Closes'!A9 | B9: ='Daily Closes'!B9 | C9: ='Daily Closes'!C9 | D9: ='Daily Closes'!D9 | E9: ='Daily Closes'!E9 | F9: — | G9: =IF('Daily Closes'!G9="","",$D9*('Daily Closes'!G9-$E9)) | H9: =IF('Daily Closes'!H9="","",$D9*('Daily Closes'!H9-$E9)) | I9: =IF('Daily Closes'!I9="","",$D9*('Daily Closes'!I9-$E9)) | J9: =IF('Daily Closes'!J9="","",$D9*('Daily Closes'!J9-$E9)) | K9: =IF('Daily Closes'!K9="","",$D9*('Daily Closes'!K9-$E9)) | L9: =IF('Daily Closes'!L9="","",$D9*('Daily Closes'!L9-$E9)) | M9: =IF('Daily Closes'!M9="","",$D9*('Daily Closes'!M9-$E9)) | N9: =IF('Daily Closes'!N9="","",$D9*('Daily Closes'!N9-$E9)) | ... AA9: =IF('Daily Closes'!AA9="","",$D9*('Daily Closes'!AA9-$E9))
A10: ='Daily Closes'!A10 | B10: ='Daily Closes'!B10 | C10: ='Daily Closes'!C10 | D10: ='Daily Closes'!D10 | E10: ='Daily Closes'!E10 | F10: — | G10: =IF('Daily Closes'!G10="","",$D10*('Daily Closes'!G10-$E10)) | H10: =IF('Daily Closes'!H10="","",$D10*('Daily Closes'!H10-$E10)) | I10: =IF('Daily Closes'!I10="","",$D10*('Daily Closes'!I10-$E10)) | J10: =IF('Daily Closes'!J10="","",$D10*('Daily Closes'!J10-$E10)) | K10: =IF('Daily Closes'!K10="","",$D10*('Daily Closes'!K10-$E10)) | L10: =IF('Daily Closes'!L10="","",$D10*('Daily Closes'!L10-$E10)) | M10: =IF('Daily Closes'!M10="","",$D10*('Daily Closes'!M10-$E10)) | N10: =IF('Daily Closes'!N10="","",$D10*('Daily Closes'!N10-$E10)) | ... AA10: =IF('Daily Closes'!AA10="","",$D10*('Daily Closes'!AA10-$E10))
A11: ='Daily Closes'!A11 | B11: ='Daily Closes'!B11 | C11: ='Daily Closes'!C11 | D11: ='Daily Closes'!D11 | E11: ='Daily Closes'!E11 | F11: — | G11: =IF('Daily Closes'!G11="","",$D11*('Daily Closes'!G11-$E11)) | H11: =IF('Daily Closes'!H11="","",$D11*('Daily Closes'!H11-$E11)) | I11: =IF('Daily Closes'!I11="","",$D11*('Daily Closes'!I11-$E11)) | J11: =IF('Daily Closes'!J11="","",$D11*('Daily Closes'!J11-$E11)) | K11: =IF('Daily Closes'!K11="","",$D11*('Daily Closes'!K11-$E11)) | L11: =IF('Daily Closes'!L11="","",$D11*('Daily Closes'!L11-$E11)) | M11: =IF('Daily Closes'!M11="","",$D11*('Daily Closes'!M11-$E11)) | N11: =IF('Daily Closes'!N11="","",$D11*('Daily Closes'!N11-$E11)) | ... AA11: =IF('Daily Closes'!AA11="","",$D11*('Daily Closes'!AA11-$E11))
A12: ='Daily Closes'!A12 | B12: ='Daily Closes'!B12 | C12: ='Daily Closes'!C12 | D12: ='Daily Closes'!D12 | E12: ='Daily Closes'!E12 | F12: — | G12: =IF('Daily Closes'!G12="","",$D12*('Daily Closes'!G12-$E12)) | H12: =IF('Daily Closes'!H12="","",$D12*('Daily Closes'!H12-$E12)) | I12: =IF('Daily Closes'!I12="","",$D12*('Daily Closes'!I12-$E12)) | J12: =IF('Daily Closes'!J12="","",$D12*('Daily Closes'!J12-$E12)) | K12: =IF('Daily Closes'!K12="","",$D12*('Daily Closes'!K12-$E12)) | L12: =IF('Daily Closes'!L12="","",$D12*('Daily Closes'!L12-$E12)) | M12: =IF('Daily Closes'!M12="","",$D12*('Daily Closes'!M12-$E12)) | N12: =IF('Daily Closes'!N12="","",$D12*('Daily Closes'!N12-$E12)) | ... AA12: =IF('Daily Closes'!AA12="","",$D12*('Daily Closes'!AA12-$E12))
A13: ='Daily Closes'!A13 | B13: ='Daily Closes'!B13 | C13: ='Daily Closes'!C13 | D13: ='Daily Closes'!D13 | E13: ='Daily Closes'!E13 | F13: — | G13: =IF('Daily Closes'!G13="","",$D13*('Daily Closes'!G13-$E13)) | H13: =IF('Daily Closes'!H13="","",$D13*('Daily Closes'!H13-$E13)) | I13: =IF('Daily Closes'!I13="","",$D13*('Daily Closes'!I13-$E13)) | J13: =IF('Daily Closes'!J13="","",$D13*('Daily Closes'!J13-$E13)) | K13: =IF('Daily Closes'!K13="","",$D13*('Daily Closes'!K13-$E13)) | L13: =IF('Daily Closes'!L13="","",$D13*('Daily Closes'!L13-$E13)) | M13: =IF('Daily Closes'!M13="","",$D13*('Daily Closes'!M13-$E13)) | N13: =IF('Daily Closes'!N13="","",$D13*('Daily Closes'!N13-$E13)) | ... AA13: =IF('Daily Closes'!AA13="","",$D13*('Daily Closes'!AA13-$E13))
A14: ='Daily Closes'!A14 | B14: ='Daily Closes'!B14 | C14: ='Daily Closes'!C14 | D14: ='Daily Closes'!D14 | E14: ='Daily Closes'!E14 | F14: — | G14: =IF('Daily Closes'!G14="","",$D14*('Daily Closes'!G14-$E14)) | H14: =IF('Daily Closes'!H14="","",$D14*('Daily Closes'!H14-$E14)) | I14: =IF('Daily Closes'!I14="","",$D14*('Daily Closes'!I14-$E14)) | J14: =IF('Daily Closes'!J14="","",$D14*('Daily Closes'!J14-$E14)) | K14: =IF('Daily Closes'!K14="","",$D14*('Daily Closes'!K14-$E14)) | L14: =IF('Daily Closes'!L14="","",$D14*('Daily Closes'!L14-$E14)) | M14: =IF('Daily Closes'!M14="","",$D14*('Daily Closes'!M14-$E14)) | N14: =IF('Daily Closes'!N14="","",$D14*('Daily Closes'!N14-$E14)) | ... AA14: =IF('Daily Closes'!AA14="","",$D14*('Daily Closes'!AA14-$E14))
A15: ='Daily Closes'!A15 | B15: ='Daily Closes'!B15 | C15: ='Daily Closes'!C15 | D15: ='Daily Closes'!D15 | E15: ='Daily Closes'!E15 | F15: — | G15: =IF('Daily Closes'!G15="","",$D15*('Daily Closes'!G15-$E15)) | H15: =IF('Daily Closes'!H15="","",$D15*('Daily Closes'!H15-$E15)) | I15: =IF('Daily Closes'!I15="","",$D15*('Daily Closes'!I15-$E15)) | J15: =IF('Daily Closes'!J15="","",$D15*('Daily Closes'!J15-$E15)) | K15: =IF('Daily Closes'!K15="","",$D15*('Daily Closes'!K15-$E15)) | L15: =IF('Daily Closes'!L15="","",$D15*('Daily Closes'!L15-$E15)) | M15: =IF('Daily Closes'!M15="","",$D15*('Daily Closes'!M15-$E15)) | N15: =IF('Daily Closes'!N15="","",$D15*('Daily Closes'!N15-$E15)) | ... AA15: =IF('Daily Closes'!AA15="","",$D15*('Daily Closes'!AA15-$E15))
B16: TOTAL | G16: =IF(COUNT(G6:G15)=0,"",SUM(G6:G15)) | H16: =IF(COUNT(H6:H15)=0,"",SUM(H6:H15)) | I16: =IF(COUNT(I6:I15)=0,"",SUM(I6:I15)) | J16: =IF(COUNT(J6:J15)=0,"",SUM(J6:J15)) | K16: =IF(COUNT(K6:K15)=0,"",SUM(K6:K15)) | L16: =IF(COUNT(L6:L15)=0,"",SUM(L6:L15)) | M16: =IF(COUNT(M6:M15)=0,"",SUM(M6:M15)) | N16: =IF(COUNT(N6:N15)=0,"",SUM(N6:N15)) | ... AA16: =IF(COUNT(AA6:AA15)=0,"",SUM(AA6:AA15))

Sheet Portfolio Path
A1: Portfolio Path — Day by Day
A2: Value, P&L, return, drawdown and Nifty 50 comparison
A4: Day | B4: Date | C4: Status | D4: Portfolio Value ₹ | E4: P&L ₹ | F4: Return % | G4: Daily % | H4: Drawdown % | I4: Nifty 50 %
A5: 0 | B5: 2026-09-28 | C5: Signal | D5: 139903 | E5: 0 | F5: 0 | I5: 0
A6: 1 | B6: 2026-09-29 | C6: Entry | D6: 145178.6 | E6: 5223.55 | F6: 0.037323 | H6: 0 | I6: -0.002812
A7: 2 | B7: 2026-09-30 | C7: Hold | D7: 144421.3 | E7: 4466.25 | F7: 0.031912 | G7: -0.005216 | H7: -0.005216 | I7: -0.007015
A8: 3 | B8: 2026-10-01 | C8: Hold | D8: 142311.25 | E8: 2356.2 | F8: 0.016835 | G8: -0.01461 | H8: -0.019751 | I8: -0.015729
A9: 4 | B9: 2026-10-02 | C9: Hold | D9: 142311.25 | E9: 2356.2 | F9: 0.016835 | G9: 0 | H9: -0.019751 | I9: -0.015729
A10: 5 | B10: 2026-10-05 | C10: Hold | D10: 144045.15 | E10: 4090.1 | F10: 0.029224 | G10: 0.012184 | H10: -0.007807 | I10: -0.009855
A11: 6 | B11: 2026-10-06 | C11: Hold | D11: 148186.35 | E11: 8231.3 | F11: 0.058814 | G11: 0.028749 | H11: 0 | I11: -0.000182
A12: 7 | B12: 2026-10-07 | C12: Hold | D12: 148825.15 | E12: 8870.1 | F12: 0.063378 | G12: 0.004311 | H12: 0 | I12: -0.007779
A13: 8 | B13: 2026-10-08 | C13: Hold | D13: 145212.55 | E13: 5257.5 | F13: 0.037566 | G13: -0.024274 | H13: -0.024274 | I13: -0.024076
A14: 9 | B14: 2026-10-09 | C14: Hold | D14: 146665.1 | E14: 6710.05 | F14: 0.047944 | G14: 0.010003 | H14: -0.014514 | I14: -0.011405
A15: 10 | B15: 2026-10-12 | C15: Hold | D15: 150238.35 | E15: 10283.3 | F15: 0.073476 | G15: 0.024363 | H15: 0 | I15: -0.018301
A16: 11 | B16: 2026-10-13 | C16: Hold | D16: 148485.25 | E16: 8530.2 | F16: 0.06095 | G16: -0.011669 | H16: -0.011669 | I16: -0.002559
A17: 12 | B17: 2026-10-14 | C17: Hold | D17: 148334.2 | E17: 8379.15 | F17: 0.05987 | G17: -0.001017 | H17: -0.012674 | I17: -0.006916
A18: 13 | B18: 2026-10-15 | C18: Hold | D18: 143337.25 | E18: 3382.2 | F18: 0.024166 | G18: -0.033687 | H18: -0.045934 | I18: 0.00953
... A23: 18 | B23: 2026-10-23 | C23: Hold | D23: 127614.75 | E23: -12340.3 | F23: -0.088173 | G23: -0.039092 | H23: -0.150585 | I23: -0.007913
A24: 19 | B24: 2026-10-27 | C24: Hold (upcoming)
A25: 20 | B25: 2026-10-28 | C25: Exit reminder (upcoming)
A26: 21 | B26: 2026-10-29 | C26: Exit (upcoming)

Sheet Batch Info
A1: Batch Details (from SwingScope HTML)
A2: SwingScope batch 2026-09-28
B4: Batch ID | C4: 2026-09-28
B5: Signal date (Day 0) | C5: 2026-09-28
B6: Exit (HTML estimate) | C6: 2026-10-27
B7: Exit (projected, NSE calendar) | C7: 2026-10-29
B8: Hold | C8: 21 sessions — no stop, no target
B9: Universe | C9: liquidity top 400 of all NSE stocks
B10: Capital committed (at signal close) | C10: 139903
B11: Estimated costs | C11: 859
B12: Cost % | C12: 0.6%
B13: Market regime | C13: Down — the signal's weakest regime historically
B14: Stocks with a warning | C14: 0 of 10
B17: # | C17: Symbol | D17: ISIN | E17: Qty | F17: Signal close | G17: Amount | H17: 12-1 % | I17: 6-1 % | J17: 3-1 % | K17: Vol % | L17: Traded daily (cr) | M17: From 12m high % | N17: Signal rank | O17: Data quality | P17: Watch
B18: 1 | C18: TDPOWERSYS | D18: INE419M01035 | E18: 20 | F18: 722 | G18: 14440 | H18: 177 | I18: 72.2 | J18: 19.6 | K18: 60.1 | L18: 128 | M18: -10.3 | N18: 6 | O18: Green | P18: Nothing flagged
B19: 2 | C19: AEROFLEX | D19: INE024001021 | E19: 29 | F19: 513.4 | G19: 14889 | H19: 175 | I19: 107 | J19: 10.7 | K19: 67.3 | L19: 53 | M19: -10.5 | N19: 7 | O19: Green | P19: Nothing flagged
B20: 3 | C20: ATHERENERG | D20: INE0LEZ01016 | E20: 10 | F20: 1454.9 | G20: 14549 | H20: 166 | I20: 97.5 | J20: 31.1 | K20: 49.4 | L20: 493 | M20: -15.7 | N20: 9 | O20: Green | P20: Nothing flagged
B21: 4 | C21: THANGAMAYL | D21: INE085J01014 | E21: 2 | F21: 5011.5 | G21: 10023 | H21: 154 | I21: 66.3 | J21: -14 | K21: 59.8 | L21: 71 | M21: -31.4 | N21: 11 | O21: Green | P21: Nothing flagged
B22: 5 | C22: RRKABEL | D22: INE777K01022 | E22: 6 | F22: 2459.8 | G22: 14759 | H22: 126 | I22: 110 | J22: 18.2 | K22: 44 | L22: 93 | M22: -16 | N22: 15 | O22: Green | P22: Nothing flagged
B23: 6 | C23: ACUTAAS | D23: INE00FF01025 | E23: 4 | F23: 3214.4 | G23: 12858 | H23: 126 | I23: 36.7 | J23: -5.6 | K23: 46.7 | L23: 101 | M23: -13 | N23: 16 | O23: Green | P23: Nothing flagged
B24: 7 | C24: DIACABS | D24: INE989C01038 | E24: 44 | F24: 339.25 | G24: 14927 | H24: 124 | I24: 180 | J24: 61.7 | K24: 53.6 | L24: 51 | M24: -14.1 | N24: 17 | O24: Green | P24: Nothing flagged
B25: 8 | C25: KIRLOSENG | D25: INE146L01010 | E25: 7 | F25: 2141.2 | G25: 14988 | H25: 123 | I25: 58.2 | J25: -11.2 | K25: 49.9 | L25: 87 | M25: -16.5 | N25: 18 | O25: Green | P25: Nothing flagged
B26: 9 | C26: E2E | D26: INE255Z01027 | E26: 23 | F26: 625.9 | G26: 14396 | H26: 109 | I26: 186 | J26: 56 | K26: 56.2 | L26: 49 | M26: -8.8 | N26: 20 | O26: Green | P26: Nothing flagged
B27: 10 | C27: LAURUSLABS | D27: INE947Q01028 | E27: 7 | F27: 2010.7 | G27: 14075 | H27: 109 | I27: 94.4 | J27: 27.2 | K27: 28.1 | L27: 300 | M27: -1.1 | N27: 21 | O27: Green | P27: Nothing flagged
B30: Evidence behind the rule (backtest, from HTML)
B31: Backtest, 2017–2026 | Replayed point in time on your survivorship-free archive. Not live results. | Signal strength | IC +0.041 | rank IC over 113 monthly dates, 2017-2026 (t 2.52); validated benchmark 0.026 | Top vs bottom decile | +1.89% | per 21-session hold, before costs (t 2.94) | Top-10 picks | +1.45% | per hold after 0.60% costs; Nifty 50 earned +1.02% before costs | Entry timing | Open wins | buying at the open beat all 30 support-entry rules (best -0.12% per hold) | Down markets | IC +0.009 | over 27 down-regime dates, against +0.050 over 86 up-regime dates
B32: Live record | No results yet | The first live result arrives when this system finishes its first batch. Live results are kept apart from the backtest and never mixed in.
B34: Corporate actions (splits, bonuses, dividends)
B35: None recorded during this hold.

Sheet Research
A1: Stock-by-Stock Research & Swing-Trade Shortlist
A2: Views from your research notes · written 2026-09-28 13:27
A4: Rank | B4: Symbol | C4: Company | D4: View | E4: Conviction | F4: Why | G4: Since entry % | H4: Call check
A5: 1 | B5: LAURUSLABS | C5: Laurus Labs | D5: Bullish | E5: 2 | F5: Relative strength near highs, lowest volatility, defensive sector | G5: -0.025090315 | H5: ✗ Off track
A6: 2 | B6: TDPOWERSYS | C6: TD Power Systems | D6: Bullish | E6: 1.5 | F6: Guidance raised, shallow pullback. Check for a fundraise. | G6: -0.1105007 | H6: ✗ Off track
A7: 3 | B7: ATHERENERG | C7: Ather Energy | D7: Bullish | E7: 1.25 | F7: Strong catalysts and brokers, but still pulling back | G7: -0.054923983 | H7: ✗ Off track
A8: 4 | B8: RRKABEL | C8: RR Kabel | D8: Moderately bullish | E8: 1 | F8: Strong Q1, moderate volatility | G8: -0.13001057 | H8: ✗ Off track
A9: 5 | B9: AEROFLEX | C9: Aeroflex Industries | D9: Bullish, risky | E9: 1.25 | F9: Strong growth, expensive, volatile, thin liquidity | G9: -0.11734794 | H9: ✗ Off track
A10: 6 | B10: E2E | C10: E2E Networks | D10: Speculative | E10: 0.5 | F10: Big revenue jump, P/E near 400 | G10: -0.086352998 | H10: ↓ Lagging
A11: 7 | B11: ACUTAAS | C11: Acutaas Chemicals | D11: Neutral | E11: 0 | F11: No catalyst, sideways trend | G11: -0.046291793 | H11: ↓ Lagging
A12: 8 | B12: DIACABS | C12: Diamond Power Infra | D12: Neutral to bearish | E12: -1 | F12: Extended, weak balance sheet | G12: -0.06485604 | H12: ✓ On track
A13: 9 | B13: KIRLOSENG | C13: Kirloskar Oil Engines | D13: Neutral to bearish | E13: -1 | F13: Margins and momentum fading | G13: -0.16649542 | H13: ✓ On track
A14: 10 | B14: THANGAMAYL | C14: Thangamayil Jewellery | D14: Bearish | E14: -2 | F14: Downtrend, avoid | G14: -0.063772455 | H14: ✓ On track
A16: STOCK BY STOCK — catalysts, risks and sources
A17: Rank | B17: Symbol | C17: Company | D17: Type | E17: Point | G17: Source | H17: Link
A18: 1 | B18: LAURUSLABS | C18: Laurus Labs | D18: Catalyst | E18: Its close is only 1.1% below its 12-month high, and its volatility is the lowest of the ten (28%).
A19: 1 | B19: LAURUSLABS | C19: Laurus Labs | D19: Catalyst | E19: FY26 profit after tax was ₹740 crore vs ₹380 crore the year before. | G19: torusdigital | H19: open ↗
A20: 1 | B20: LAURUSLABS | C20: Laurus Labs | D20: Catalyst | E20: It is up about 94% in six months and holding near highs while the index falls. | G20: anandrathi | H20: open ↗
A21: 1 | B21: LAURUSLABS | C21: Laurus Labs | D21: Catalyst | E21: Pharma is also defensive in a risk-off tape. | G21: anandrathi | H21: open ↗
A22: 1 | B22: LAURUSLABS | C22: Laurus Labs | D22: Risk | E22: P/E is high, so it can still pull back. | G22: anandrathi | H22: open ↗
A23: 2 | B23: TDPOWERSYS | C23: TD Power Systems | D23: Context | E23: The stock is 10% below its high, a shallow pullback within a strong uptrend.
A24: 2 | B24: TDPOWERSYS | C24: TD Power Systems | D24: Catalyst | E24: Q1 FY27 revenue rose about 72% YoY. | G24: 5paisa | H24: open ↗
A25: 2 | B25: TDPOWERSYS | C25: TD Power Systems | D25: Catalyst | E25: It raised its FY27 revenue guidance to ₹2,600 crore. | G25: fyers | H25: open ↗
A26: 2 | B26: TDPOWERSYS | C26: TD Power Systems | D26: Risk | E26: A board meeting on 14 Aug was set to consider raising funds, so check whether a dilutive QIP is pending. | G26: 5paisa | H26: open ↗
A27: 2 | B27: TDPOWERSYS | C27: TD Power Systems | D27: Risk | E27: Valuation is stretched (P/E around 70). | G27: 5paisa | H27: open ↗
A28: 3 | B28: ATHERENERG | C28: Ather Energy | D28: Catalyst | E28: Q1 revenue grew 89% and the loss narrowed 71%. | G28: indmoney | H28: open ↗
A29: 3 | B29: ATHERENERG | C29: Ather Energy | D29: Catalyst | E29: It was also added to the MSCI India Domestic Small Cap Index. | G29: indmoney | H29: open ↗
A30: 3 | B30: ATHERENERG | C30: Ather Energy | D30: Catalyst | E30: Hero MotoCorp is lifting its stake to about 32.8%. | G30: freepressjournal | H30: open ↗
A31: 3 | B31: ATHERENERG | C31: Ather Energy | D31: Catalyst | E31: A global broker raised its target to ₹1,926. | G31: hdfcsky | H31: open ↗
A32: 3 | B32: ATHERENERG | C32: Ather Energy | D32: Context | E32: The stock has slid about 16% from its early-September high, so the story is intact but the price is digesting a big run.
A33: 3 | B33: ATHERENERG | C33: Ather Energy | D33: Catalyst | E33: High oil prices are a tailwind for the EV theme.
A34: 4 | B34: RRKABEL | C34: RR Kabel | D34: Catalyst | E34: Q1 PAT jumped 129% and EBITDA doubled. | G34: 5paisa | H34: open ↗
A35: 4 | B35: RRKABEL | C35: RR Kabel | D35: Catalyst | E35: CLSA initiated at Outperform with a ₹2,850 target. | G35: fyers | H35: open ↗
A36: 4 | B36: RRKABEL | C36: RR Kabel | D36: Context | E36: The stock is 16% off its high, so it is consolidating.
A37: 4 | B37: RRKABEL | C37: RR Kabel | D37: Catalyst | E37: Volatility is moderate (44%), which is better than most here.
A38: 5 | B38: AEROFLEX | C38: Aeroflex Industries | D38: Catalyst | E38: Q1 FY27 revenue grew 72.4% and PAT rose 162%. | G38: sahi | H38: open ↗
A39: 5 | B39: AEROFLEX | C39: Aeroflex Industries | D39: Catalyst | E39: Liquid-cooling skid capacity was raised 50%, with further expansion planned. | G39: sahi | H39: open ↗
A40: 5 | B40: AEROFLEX | C40: Aeroflex Industries | D40: Risk | E40: P/E is about 102, volatility is the highest of the ten (67%), and liquidity is thin (₹53 cr/day). | G40: share | H40: open ↗
A41: 5 | B41: AEROFLEX | C41: Aeroflex Industries | D41: Risk | E41: That makes it the most fragile in a falling market. | G41: share | H41: open ↗
A42: 6 | B42: E2E | C42: E2E Networks | D42: Catalyst | E42: Q1 revenue was ₹156.76 crore vs ₹36.11 crore a year earlier, with a profit of ₹43.88 crore, on GPU cluster expansion. | G42: angelone | H42: open ↗
...

Sheet News & Sentiment
A1: Positive News & Sentiment
A2: Fetched 2026-10-23 17:22
A4: Symbol | B4: Published | C4: Headline | D4: Source | E4: Sentiment | F4: Label | G4: Link
A5: MARKET | B5: 2026-10-23 16:48 | C5: Sensex, Nifty Extend Losing Streak to Fourth Session as Crude Surges above $114 | D5: The Indian Awaaz | E5: 0.077 | F5: Neutral | G5: open ↗
A6: MARKET | B6: 2026-10-23 15:07 | C6: Sensex, Nifty Fall for Fourth Consecutive Session as Geopolitical Tensions Rattle Indian Markets | D6: INDIA New England News | E6: -0.34 | F6: Negative | G6: open ↗
A7: AEROFLEX | B7: 2026-10-23 14:26 | C7: Aeroflex Enterprises NSE:AEROENTER Stilonn Acquisition | D7: Kalkine India | E7: 0 | F7: Neutral | G7: open ↗
A8: MARKET | B8: 2026-10-23 13:04 | C8: Stock Market Weekly Wrap: Rs 16 lakh crore mcap wiped out as Sensex sheds 1,605 points — what lies ahead? | D8: Zee Business | E8: -0.66 | F8: Negative | G8: open ↗
A9: MARKET | B9: 2026-10-23 12:56 | C9: Indian Renewable Energy Stocks Decline as Inox Wind Falls 5.45% on October 23 | D9: SolarQuarter | E9: -0.477 | F9: Negative | G9: open ↗
A10: MARKET | B10: 2026-10-23 12:00 | C10: Market wrap: Eternal, Apollo Hospital, Shriram Finance, Adani Enterprises among top gainers and losers on | D10: The Economic Times | E10: -0.382 | F10: Negative | G10: open ↗
A11: MARKET | B11: 2026-10-23 11:34 | C11: Sensex Fall Today: Sensex Drops 1,279 Points, Nifty Near 22,400 | D11: Business Outreach Magazine | E11: 0.077 | F11: Neutral | G11: open ↗
A12: MARKET | B12: 2026-10-23 11:22 | C12: Share Market Today: Nifty 50, Bank Nifty | Oct 23, 2026 | D12: Liquide Blog | E12: 0.66 | F12: Positive | G12: open ↗
A13: MARKET | B13: 2026-10-23 11:20 | C13: Indian Equities Fall for Fourth Day as West Asia Tensions Drive Oil Prices Higher | D13: Rediff | E13: -0.625 | F13: Negative | G13: open ↗
A14: MARKET | B14: 2026-10-23 11:19 | C14: Markets extend losses for 4th day amid selling pressure, oil price surge | D14: DT Next | E14: -0.026 | F14: Neutral | G14: open ↗
A15: MARKET | B15: 2026-10-23 10:54 | C15: Markets Fall for 4th Day as Crude Nears $114; Nifty Ends at 22,600 | D15: HDFC Sky | E15: -0.527 | F15: Negative | G15: open ↗
A16: MARKET | B16: 2026-10-23 10:46 | C16: Sensex Today Ends 126 Points lower | Nifty Below 22,650 | Tata Steel Drown 3% | D16: Equitymaster | E16: -0.421 | F16: Negative | G16: open ↗
... A135: E2E | B135: 2026-10-16 21:00 | C135: E2E Networks Ltd (NSE:E2E) Q2 2027 Earnings Call Highlights: Revenue Surges 411% YoY on ... | D135: Yahoo Finance | E135: 0.494 | F135: Positive | G135: open ↗

Sheet _state
